<?xml version="1.0"?>
<robot name="my_robot">

    <!-- base link !-->
    <link name="base_link">
        <visual>
            <geometry>
                <box size="0.4 0.4 0.1"/>
            </geometry>
            <origin xyz="0 0 0.05" rpy="0 0 0"/>
            <material name="blue">
                <color rgba="0 0 1.0 1"/>
            </material>
        </visual>
    </link>

    <!-- link1 !-->
    <link name="link1">
        <visual>
            <geometry>
                <cylinder length="0.5" radius="0.1"/>
            </geometry>
            <origin xyz="0 0 0.25" rpy="0 0 0"/>
            <material name="green">
                <color rgba="0 0.8 0 1"/>
            </material>
        </visual>
    </link>

    <!-- joint1 !-->
    <joint name="joint1" type="revolute">
        <parent link="base_link"/>
        <child link="link1"/>
        <origin xyz="0 0 0.1" rpy="0 0 0"/>
        <axis xyz="0 0 1"/>
        <limit effort="1000.0" velocity="1.0" lower="-3.14159" upper="3.14159"/>
    </joint>

    <!-- link2 !-->
    <link name="link2">
        <visual>
            <geometry>
                <cylinder length="0.6" radius="0.05"/>
            </geometry>
            <origin xyz="0 0 0.3" rpy="0 0 0"/>
            <material name="red">
                <color rgba="0.8 0 0 1"/>
            </material>
        </visual>
    </link>

    <!-- joint2 !-->
    <joint name="joint2" type="revolute">
        <parent link="link1"/>
        <child link="link2"/>
        <origin xyz="0 0 0.5" rpy="0 0 0"/>
        <axis xyz="0 1 0"/>
        <limit effort="1000.0" velocity="1.0" lower="0" upper="2.5"/>
    </joint>

    <!-- link3 !-->
    <link name="link3">
        <visual>
            <geometry>
                <cylinder length="0.1" radius="0.05"/>
            </geometry>
            <origin xyz="0 0 0.05" rpy="0 0 0"/>
            <material name="yellow">
                <color rgba="0.8 0.8 0 1"/>
            </material>
        </visual>
    </link>

    <!-- joint3 !-->
    <joint name="joint3" type="revolute">
        <parent link="link2"/>
        <child link="link3"/>
        <origin xyz="0 0 0.6" rpy="0 0 0"/>
        <axis xyz="0 1 0"/>
        <limit effort="1000.0" velocity="1.0" lower="0" upper="2.5"/>
    </joint>

    <!-- link4 !-->
    <link name="link4">
        <visual>
            <geometry>
                <cylinder length="0.5" radius="0.05"/>
            </geometry>
            <origin xyz="0 0 0.25" rpy="0 0 0"/>
            <material name="cyan">
                <color rgba="0 0.8 0.8 1"/>
            </material>
        </visual>
    </link>

    <!-- joint4 !-->
    <joint name="joint4" type="revolute">
        <parent link="link3"/>
        <child link="link4"/>
        <origin xyz="0 0 0.1" rpy="0 0 0"/>
        <axis xyz="0 0 1"/>
        <limit effort="1000.0" velocity="1.0" lower="-3.14159" upper="3.14159"/>
    </joint>

    <!-- link5 !-->
    <link name="link5">
        <visual>
            <geometry>
                <box size="0.1 0.1 0.05"/>
            </geometry>
            <origin xyz="0 0 0.025" rpy="0 0 0"/>
            <material name="purple">
                <color rgba="0.8 0 0.8 1"/>
            </material>
        </visual>
    </link>

    <!-- joint5 !-->
    <joint name="joint5" type="revolute">
        <parent link="link4"/>
        <child link="link5"/>
        <origin xyz="0 0 0.5" rpy="0 0 0"/>
        <axis xyz="0 1 0"/>
        <limit effort="1000.0" velocity="1.0" lower="-1.5708" upper="1.5708"/>
    </joint>

    <!-- link6 !-->
    <link name="link6">
        <visual>
            <geometry>
                <box size="0.1 0.1 0.02"/>
            </geometry>
            <origin xyz="0 0 0.01" rpy="0 0 0"/>
            <material name="orange">
                <color rgba="1.0 0.6 0 1"/>
            </material>
        </visual>
    </link>

    <!-- joint6 !-->
    <joint name="joint6" type="continuous">
        <parent link="link5"/>
        <child link="link6"/>
        <origin xyz="0 0 0.05" rpy="0 0 0"/>
        <axis xyz="0 0 1"/>
        <!--limit effort="1000.0" velocity="1.0" lower="-3.14159" upper="3.14159"/-->
    </joint>

    <!-- tool_link !-->
    <link name="tool_link"/>

    <!-- tool_joint !-->
    <joint name="tool_joint" type="fixed">
        <parent link="link6"/>
        <child link="tool_link"/>
        <origin xyz="0 0 0.02" rpy="0 0 0"/>
    </joint>

</robot>